Workbook
Name a: #REF!

Sheet Cleaning schedule
B1: Confirmation code | C1: Status | D1: Guest name | E1: Contact | F1: # of adults | G1: # of children | H1: # of infants | I1: Start date | J1: End date | K1: # of nights | L1: Booked | M1: Listing | N1: Earnings | O1: Properties | R1: Walk Through before guest check in | T1: Clean up after guests check out | U1: Airbnb/VRBO | V1: Check 1 | Y1: Check | Z1: Check for conflicts
B2: Directly | C2: Booked | D2: Kitti Teso | I2: 45611 | J2: 45991 | N2: 8750 | O2: 65th Terr | U2: =IF(LEFT(B2,2)="HM","AIRBNB",IF(LEFT(B2,2)="HA","VRBO",IF(LEFT(B2,2)="Di","Directly","Owner staying"))) -> Directly | V2: =IF(COUNTIF($I:$I,$J2)>0,"Same day check in "&COUNTIF($I:$I,$J2)&" houses",0) -> 0 | W2: =I2&O2 -> 4561165th Terr | X2: =J2&O2 -> 4599165th Terr | Y2: =IF(COUNTIF($W:$W,$X2)>0,"Check in, check out on the same day of stay "&O2,0) -> 0 | Z2: =IF(SUMPRODUCT(($O$2:$O$10000=$O2)*($I$2:$I$10000<J2)*($J$2:$J$10000>I2))>1,"Conflict","")
B3: HMXN3KWYJM | C3: Currently hosting | D3: Saul Maldonado | E3: +1 904-400-8298 | F3: 5 | G3: 0 | H3: 0 | I3: 45807 | J3: 45900 | K3: 93 | L3: 45799 | M3: 119th Terrace Vacation Home in Largo | N3: 12879.66 | O3: 119th | U3: =IF(LEFT(B3,2)="HM","AIRBNB",IF(LEFT(B3,2)="HA","VRBO",IF(LEFT(B3,2)="Di","Directly","Owner staying"))) -> AIRBNB | V3: =IF(COUNTIF($I:$I,$J3)>0,"Same day check in "&COUNTIF($I:$I,$J3)&" houses",0) -> 0 | W3: =I3&O3 -> 45807119th | X3: =J3&O3 -> 45900119th | Y3: =IF(COUNTIF($W:$W,$X3)>0,"Check in, check out on the same day of stay "&O3,0) -> 0 | Z3: =IF(SUMPRODUCT(($O$2:$O$10000=$O3)*($I$2:$I$10000<J3)*($J$2:$J$10000>I3))>1,"Conflict","")
B4: HM8WB5JKHZ | C4: Currently hosting | D4: Alan Salas | E4: +1 303-901-9414 | F4: 6 | G4: 0 | H4: 0 | I4: 45823 | J4: 45929 | K4: 106 | L4: 45820 | M4: 49th Ave Gem in Lealman area | N4: 9574.77 | O4: 4877 49th Ave N | U4: =IF(LEFT(B4,2)="HM","AIRBNB",IF(LEFT(B4,2)="HA","VRBO",IF(LEFT(B4,2)="Di","Directly","Owner staying"))) -> AIRBNB | V4: =IF(COUNTIF($I:$I,$J4)>0,"Same day check in "&COUNTIF($I:$I,$J4)&" houses",0) -> 0 | W4: =I4&O4 -> 458234877 49th Ave N | X4: =J4&O4 -> 459294877 49th Ave N | Y4: =IF(COUNTIF($W:$W,$X4)>0,"Check in, check out on the same day of stay "&O4,0) -> 0 | Z4: =IF(SUMPRODUCT(($O$2:$O$10000=$O4)*($I$2:$I$10000<J4)*($J$2:$J$10000>I4))>1,"Conflict","")
B5: Owner staying | C5: Owner staying | D5: Mike Lam | I5: 45880 | J5: 45941 | O5: Canterbury | U5: =IF(LEFT(B5,2)="HM","AIRBNB",IF(LEFT(B5,2)="HA","VRBO",IF(LEFT(B5,2)="Di","Directly","Owner staying"))) -> Owner staying | V5: =IF(COUNTIF($I:$I,$J5)>0,"Same day check in "&COUNTIF($I:$I,$J5)&" houses",0) -> Same day check in 1 houses | W5: =I5&O5 -> 45880Canterbury | X5: =J5&O5 -> 45941Canterbury | Y5: =IF(COUNTIF($W:$W,$X5)>0,"Check in, check out on the same day of stay "&O5,0) -> 0 | Z5: =IF(SUMPRODUCT(($O$2:$O$10000=$O5)*($I$2:$I$10000<J5)*($J$2:$J$10000>I5))>1,"Conflict","")
B6: HMDTQQCJJM | C6: Currently hosting | D6: Richard Solomon | E6: +1 332-323-7280 | F6: 1 | G6: 2 | H6: 0 | I6: 45886 | J6: 45900 | K6: 14 | L6: 45877 | M6: Sheldon Chase - the Cozy Tampa Retreat with POOL | N6: 2435.09 | O6: Sheldon Chase | U6: =IF(LEFT(B6,2)="HM","AIRBNB",IF(LEFT(B6,2)="HA","VRBO",IF(LEFT(B6,2)="Di","Directly","Owner staying"))) -> AIRBNB | V6: =IF(COUNTIF($I:$I,$J6)>0,"Same day check in "&COUNTIF($I:$I,$J6)&" houses",0) -> 0 | W6: =I6&O6 -> 45886Sheldon Chase | X6: =J6&O6 -> 45900Sheldon Chase | Y6: =IF(COUNTIF($W:$W,$X6)>0,"Check in, check out on the same day of stay "&O6,0) -> 0 | Z6: =IF(SUMPRODUCT(($O$2:$O$10000=$O6)*($I$2:$I$10000<J6)*($J$2:$J$10000>I6))>1,"Conflict","")
B7: HM8YAQYQMS | C7: Currently hosting | D7: Tanisha Louisa | E7: +1 502-540-9010 | F7: 3 | G7: 0 | H7: 0 | I7: 45894 | J7: 45897 | K7: 3 | L7: 45834 | M7: Toucan Luxury Oasis - Heated POOL and SPA | N7: 1057.3 | O7: Toucan | U7: =IF(LEFT(B7,2)="HM","AIRBNB",IF(LEFT(B7,2)="HA","VRBO",IF(LEFT(B7,2)="Di","Directly","Owner staying"))) -> AIRBNB | V7: =IF(COUNTIF($I:$I,$J7)>0,"Same day check in "&COUNTIF($I:$I,$J7)&" houses",0) -> Same day check in 2 houses | W7: =I7&O7 -> 45894Toucan | X7: =J7&O7 -> 45897Toucan | Y7: =IF(COUNTIF($W:$W,$X7)>0,"Check in, check out on the same day of stay "&O7,0) -> 0 | Z7: =IF(SUMPRODUCT(($O$2:$O$10000=$O7)*($I$2:$I$10000<J7)*($J$2:$J$10000>I7))>1,"Conflict","")
B8: Owner staying | C8: Owner staying | D8: Duy Lam | I8: 45896 | J8: 45903 | O8: 54th Ave | U8: =IF(LEFT(B8,2)="HM","AIRBNB",IF(LEFT(B8,2)="HA","VRBO",IF(LEFT(B8,2)="Di","Directly","Owner staying"))) -> Owner staying | V8: =IF(COUNTIF($I:$I,$J8)>0,"Same day check in "&COUNTIF($I:$I,$J8)&" houses",0) -> 0 | W8: =I8&O8 -> 4589654th Ave | X8: =J8&O8 -> 4590354th Ave | Y8: =IF(COUNTIF($W:$W,$X8)>0,"Check in, check out on the same day of stay "&O8,0) -> 0 | Z8: =IF(SUMPRODUCT(($O$2:$O$10000=$O8)*($I$2:$I$10000<J8)*($J$2:$J$10000>I8))>1,"Conflict","")
B9: HMKTWZ9YP3 | C9: Confirmed | D9: Alice Hunt | E9: +1 812-989-6895 | F9: 3 | G9: 0 | H9: 0 | I9: 45897 | J9: 45901 | K9: 4 | L9: 45893 | M9: 102nd Pinellas Park home w/ screened POOL | N9: 986.49 | O9: 102nd | U9: =IF(LEFT(B9,2)="HM","AIRBNB",IF(LEFT(B9,2)="HA","VRBO",IF(LEFT(B9,2)="Di","Directly","Owner staying"))) -> AIRBNB | V9: =IF(COUNTIF($I:$I,$J9)>0,"Same day check in "&COUNTIF($I:$I,$J9)&" houses",0) -> 0 | W9: =I9&O9 -> 45897102nd | X9: =J9&O9 -> 45901102nd | Y9: =IF(COUNTIF($W:$W,$X9)>0,"Check in, check out on the same day of stay "&O9,0) -> 0 | Z9: =IF(SUMPRODUCT(($O$2:$O$10000=$O9)*($I$2:$I$10000<J9)*($J$2:$J$10000>I9))>1,"Conflict","")
B10: HMDNHY93WB | C10: Confirmed | D10: Tony Martinez | E10: +1 239-784-1118 | F10: 4 | G10: 0 | H10: 0 | I10: 45897 | J10: 45901 | K10: 4 | L10: 45875 | M10: Elmhurst Getaway Home w/ screened POOL | N10: 1028.2 | O10: Elmhurst | U10: =IF(LEFT(B10,2)="HM","AIRBNB",IF(LEFT(B10,2)="HA","VRBO",IF(LEFT(B10,2)="Di","Directly","Owner staying"))) -> AIRBNB | V10: =IF(COUNTIF($I:$I,$J10)>0,"Same day check in "&COUNTIF($I:$I,$J10)&" houses",0) -> 0 | W10: =I10&O10 -> 45897Elmhurst | X10: =J10&O10 -> 45901Elmhurst | Y10: =IF(COUNTIF($W:$W,$X10)>0,"Check in, check out on the same day of stay "&O10,0) -> 0 | Z10: =IF(SUMPRODUCT(($O$2:$O$10000=$O10)*($I$2:$I$10000<J10)*($J$2:$J$10000>I10))>1,"Conflict","")
B11: HMWATRPE8R | C11: Confirmed | D11: Daimar Diaz | E11: +1 470-938-5194 | F11: 1 | G11: 0 | H11: 0 | I11: 45898 | J11: 45901 | K11: 3 | L11: 45895 | M11: Hidden Gem in Oakhurst Area - 4 mins to the Beach | N11: 910.83 | O11: 106th Ave | U11: =IF(LEFT(B11,2)="HM","AIRBNB",IF(LEFT(B11,2)="HA","VRBO",IF(LEFT(B11,2)="Di","Directly","Owner staying"))) -> AIRBNB | V11: =IF(COUNTIF($I:$I,$J11)>0,"Same day check in "&COUNTIF($I:$I,$J11)&" houses",0) -> 0 | W11: =I11&O11 -> 45898106th Ave | X11: =J11&O11 -> 45901106th Ave | Y11: =IF(COUNTIF($W:$W,$X11)>0,"Check in, check out on the same day of stay "&O11,0) -> 0 | Z11: =IF(SUMPRODUCT(($O$2:$O$10000=$O11)*($I$2:$I$10000<J11)*($J$2:$J$10000>I11))>1,"Conflict","")
B12: HMQ3KMQNX9 | C12: Confirmed | D12: Sandra Elliott | E12: +1 585-506-7169 | F12: 6 | G12: 0 | H12: 1 | I12: 45898 | J12: 45901 | K12: 3 | L12: 45835 | M12: Pinellas Coastal: Pool & Jacuzzi Vacation Home | N12: 848.75 | O12: 64th Street | U12: =IF(LEFT(B12,2)="HM","AIRBNB",IF(LEFT(B12,2)="HA","VRBO",IF(LEFT(B12,2)="Di","Directly","Owner staying"))) -> AIRBNB | V12: =IF(COUNTIF($I:$I,$J12)>0,"Same day check in "&COUNTIF($I:$I,$J12)&" houses",0) -> 0 | W12: =I12&O12 -> 4589864th Street | X12: =J12&O12 -> 4590164th Street | Y12: =IF(COUNTIF($W:$W,$X12)>0,"Check in, check out on the same day of stay "&O12,0) -> 0 | Z12: =IF(SUMPRODUCT(($O$2:$O$10000=$O12)*($I$2:$I$10000<J12)*($J$2:$J$10000>I12))>1,"Conflict","")
B13: HMHCA35ERM | C13: Confirmed | D13: Alexandria Ezquerra | E13: +1 904-814-5441 | F13: 8 | G13: 0 | H13: 0 | I13: 45898 | J13: 45901 | K13: 3 | L13: 45769 | M13: Sunrise Escape waterfront - pool heater avail | N13: 1843.97 | O13: Sunrise | U13: =IF(LEFT(B13,2)="HM","AIRBNB",IF(LEFT(B13,2)="HA","VRBO",IF(LEFT(B13,2)="Di","Directly","Owner staying"))) -> AIRBNB | V13: =IF(COUNTIF($I:$I,$J13)>0,"Same day check in "&COUNTIF($I:$I,$J13)&" houses",0) -> 0 | W13: =I13&O13 -> 45898Sunrise | X13: =J13&O13 -> 45901Sunrise | Y13: =IF(COUNTIF($W:$W,$X13)>0,"Check in, check out on the same day of stay "&O13,0) -> 0 | Z13: =IF(SUMPRODUCT(($O$2:$O$10000=$O13)*($I$2:$I$10000<J13)*($J$2:$J$10000>I13))>1,"Conflict","")
B14: HM3WRJAT4Y | C14: Confirmed | D14: Willie Will | E14: +1 501-230-3169 | F14: 5 | G14: 0 | H14: 0 | I14: 45898 | J14: 45902 | K14: 4 | L14: 45851 | M14: Oceanfront Getaway, boat dock, pool heating avail | N14: 1735.33 | O14: 11523 48th | U14: =IF(LEFT(B14,2)="HM","AIRBNB",IF(LEFT(B14,2)="HA","VRBO",IF(LEFT(B14,2)="Di","Directly","Owner staying"))) -> AIRBNB | V14: =IF(COUNTIF($I:$I,$J14)>0,"Same day check in "&COUNTIF($I:$I,$J14)&" houses",0) -> 0 | W14: =I14&O14 -> 4589811523 48th | X14: =J14&O14 -> 4590211523 48th | Y14: =IF(COUNTIF($W:$W,$X14)>0,"Check in, check out on the same day of stay "&O14,0) -> 0 | Z14: =IF(SUMPRODUCT(($O$2:$O$10000=$O14)*($I$2:$I$10000<J14)*($J$2:$J$10000>I14))>1,"Conflict","")
B15: Owner staying | C15: Owner staying | D15: Chi Lan Anh | I15: 45898 | J15: 45902 | O15: 4801 48th | U15: =IF(LEFT(B15,2)="HM","AIRBNB",IF(LEFT(B15,2)="HA","VRBO",IF(LEFT(B15,2)="Di","Directly","Owner staying"))) -> Owner staying | V15: =IF(COUNTIF($I:$I,$J15)>0,"Same day check in "&COUNTIF($I:$I,$J15)&" houses",0) -> 0 | W15: =I15&O15 -> 458984801 48th | X15: =J15&O15 -> 459024801 48th | Y15: =IF(COUNTIF($W:$W,$X15)>0,"Check in, check out on the same day of stay "&O15,0) -> 0 | Z15: =IF(SUMPRODUCT(($O$2:$O$10000=$O15)*($I$2:$I$10000<J15)*($J$2:$J$10000>I15))>1,"Conflict","")
B16: HMREP2ZWED | C16: Confirmed | D16: Zoey Manasakis | E16: +1 516-286-0702 | F16: 2 | G16: 0 | H16: 0 | I16: 45898 | J16: 45903 | K16: 5 | L16: 45877 | M16: Lake Valencia Cove - Pool Heating Avail | N16: 1691.68 | O16: Lake Valencia | U16: =IF(LEFT(B16,2)="HM","AIRBNB",IF(LEFT(B16,2)="HA","VRBO",IF(LEFT(B16,2)="Di","Directly","Owner staying"))) -> AIRBNB | V16: =IF(COUNTIF($I:$I,$J16)>0,"Same day check in "&COUNTIF($I:$I,$J16)&" houses",0) -> 0 | W16: =I16&O16 -> 45898Lake Valencia | X16: =J16&O16 -> 45903Lake Valencia | Y16: =IF(COUNTIF($W:$W,$X16)>0,"Check in, check out on the same day of stay "&O16,0) -> 0 | Z16: =IF(SUMPRODUCT(($O$2:$O$10000=$O16)*($I$2:$I$10000<J16)*($J$2:$J$10000>I16))>1,"Conflict","")
B17: Owner staying | C17: Owner staying | D17: Chi Lan Anh | I17: 45905 | J17: 45907 | O17: 4801 48th | U17: =IF(LEFT(B17,2)="HM","AIRBNB",IF(LEFT(B17,2)="HA","VRBO",IF(LEFT(B17,2)="Di","Directly","Owner staying"))) -> Owner staying | V17: =IF(COUNTIF($I:$I,$J17)>0,"Same day check in "&COUNTIF($I:$I,$J17)&" houses",0) -> Same day check in 1 houses | W17: =I17&O17 -> 459054801 48th | X17: =J17&O17 -> 459074801 48th | Y17: =IF(COUNTIF($W:$W,$X17)>0,"Check in, check out on the same day of stay "&O17,0) -> 0 | Z17: =IF(SUMPRODUCT(($O$2:$O$10000=$O17)*($I$2:$I$10000<J17)*($J$2:$J$10000>I17))>1,"Conflict","")
B18: HMS2HSHWEX | C18: Confirmed | D18: Ralph Williams | E18: +1 352-603-2677 | F18: 3 | G18: 0 | H18: 0 | I18: 45905 | J18: 45908 | K18: 3 | L18: 45894 | M18: Oceanfront Getaway, boat dock, pool heating avail | N18: 1338.6 | O18: 11523 48th | U18: =IF(LEFT(B18,2)="HM","AIRBNB",IF(LEFT(B18,2)="HA","VRBO",IF(LEFT(B18,2)="Di","Directly","Owner staying"))) -> AIRBNB | V18: =IF(COUNTIF($I:$I,$J18)>0,"Same day check in "&COUNTIF($I:$I,$J18)&" houses",0) -> 0 | W18: =I18&O18 -> 4590511523 48th | X18: =J18&O18 -> 4590811523 48th | Y18: =IF(COUNTIF($W:$W,$X18)>0,"Check in, check out on the same day of stay "&O18,0) -> 0 | Z18: =IF(SUMPRODUCT(($O$2:$O$10000=$O18)*($I$2:$I$10000<J18)*($J$2:$J$10000>I18))>1,"Conflict","")
B19: HMSDEMQP5T | C19: Confirmed | D19: Candice Cain | E19: +1 631-813-0815 | F19: 6 | G19: 0 | H19: 0 | I19: 45907 | J19: 45934 | K19: 27 | L19: 45888 | M19: Coastal Breeze on 66th Avenue | N19: 4976.78 | O19: 66th Ave | U19: =IF(LEFT(B19,2)="HM","AIRBNB",IF(LEFT(B19,2)="HA","VRBO",IF(LEFT(B19,2)="Di","Directly","Owner staying"))) -> AIRBNB | V19: =IF(COUNTIF($I:$I,$J19)>0,"Same day check in "&COUNTIF($I:$I,$J19)&" houses",0) -> 0 | W19: =I19&O19 -> 4590766th Ave | X19: =J19&O19 -> 4593466th Ave | Y19: =IF(COUNTIF($W:$W,$X19)>0,"Check in, check out on the same day of stay "&O19,0) -> 0 | Z19: =IF(SUMPRODUCT(($O$2:$O$10000=$O19)*($I$2:$I$10000<J19)*($J$2:$J$10000>I19))>1,"Conflict","")
B20: HMKTYFAC3E | C20: Confirmed | D20: Jacqueline Cornell | E20: +1 601-678-2596 | F20: 6 | G20: 0 | H20: 0 | I20: 45911 | J20: 45914 | K20: 3 | L20: 45890 | M20: Sunrise Escape waterfront - pool heater avail | N20: 1387.1 | O20: Sunrise | U20: =IF(LEFT(B20,2)="HM","AIRBNB",IF(LEFT(B20,2)="HA","VRBO",IF(LEFT(B20,2)="Di","Directly","Owner staying"))) -> AIRBNB | V20: =IF(COUNTIF($I:$I,$J20)>0,"Same day check in "&COUNTIF($I:$I,$J20)&" houses",0) -> Same day check in 1 houses | W20: =I20&O20 -> 45911Sunrise | X20: =J20&O20 -> 45914Sunrise | Y20: =IF(COUNTIF($W:$W,$X20)>0,"Check in, check out on the same day of stay "&O20,0) -> 0 | Z20: =IF(SUMPRODUCT(($O$2:$O$10000=$O20)*($I$2:$I$10000<J20)*($J$2:$J$10000>I20))>1,"Conflict","")
B21: Owner staying | C21: Owner staying | D21: Chi Lan Anh | I21: 45912 | J21: 45915 | O21: 4801 48th | U21: =IF(LEFT(B21,2)="HM","AIRBNB",IF(LEFT(B21,2)="HA","VRBO",IF(LEFT(B21,2)="Di","Directly","Owner staying"))) -> Owner staying | V21: =IF(COUNTIF($I:$I,$J21)>0,"Same day check in "&COUNTIF($I:$I,$J21)&" houses",0) -> 0 | W21: =I21&O21 -> 459124801 48th | X21: =J21&O21 -> 459154801 48th | Y21: =IF(COUNTIF($W:$W,$X21)>0,"Check in, check out on the same day of stay "&O21,0) -> 0 | Z21: =IF(SUMPRODUCT(($O$2:$O$10000=$O21)*($I$2:$I$10000<J21)*($J$2:$J$10000>I21))>1,"Conflict","")
B22: HMD2QJS3YA | C22: Confirmed | D22: Eric Wildberger | E22: +55 71 99300-1662 | F22: 1 | G22: 0 | H22: 0 | I22: 45914 | J22: 45933 | K22: 19 | L22: 45891 | M22: 76th Av Pinellas Park Centralized & Spacious House | N22: 2699.12 | O22: 76th Ave | U22: =IF(LEFT(B22,2)="HM","AIRBNB",IF(LEFT(B22,2)="HA","VRBO",IF(LEFT(B22,2)="Di","Directly","Owner staying"))) -> AIRBNB | V22: =IF(COUNTIF($I:$I,$J22)>0,"Same day check in "&COUNTIF($I:$I,$J22)&" houses",0) -> 0 | W22: =I22&O22 -> 4591476th Ave | X22: =J22&O22 -> 4593376th Ave | Y22: =IF(COUNTIF($W:$W,$X22)>0,"Check in, check out on the same day of stay "&O22,0) -> 0 | Z22: =IF(SUMPRODUCT(($O$2:$O$10000=$O22)*($I$2:$I$10000<J22)*($J$2:$J$10000>I22))>1,"Conflict","")
B23: HMEDBYH9HM | C23: Confirmed | D23: Luis Romero | E23: +1 786-797-1915 | F23: 6 | G23: 2 | H23: 0 | I23: 45919 | J23: 45925 | K23: 6 | L23: 45888 | M23: Sunrise Escape waterfront - pool heater avail | N23: 2725.7 | O23: Sunrise | U23: =IF(LEFT(B23,2)="HM","AIRBNB",IF(LEFT(B23,2)="HA","VRBO",IF(LEFT(B23,2)="Di","Directly","Owner staying"))) -> AIRBNB | V23: =IF(COUNTIF($I:$I,$J23)>0,"Same day check in "&COUNTIF($I:$I,$J23)&" houses",0) -> Same day check in 1 houses | W23: =I23&O23 -> 45919Sunrise | X23: =J23&O23 -> 45925Sunrise | Y23: =IF(COUNTIF($W:$W,$X23)>0,"Check in, check out on the same day of stay "&O23,0) -> Check in, check out on the same day of stay Sunrise | Z23: =IF(SUMPRODUCT(($O$2:$O$10000=$O23)*($I$2:$I$10000<J23)*($J$2:$J$10000>I23))>1,"Conflict","")
B24: HM4SENNDYM | C24: Confirmed | D24: Susan Signer | E24: +1 815-990-4519 | F24: 7 | G24: 0 | H24: 0 | I24: 45925 | J24: 45928 | K24: 3 | L24: 45880 | M24: Sunrise Escape waterfront - pool heater avail | N24: 1459.85 | O24: Sunrise | U24: =IF(LEFT(B24,2)="HM","AIRBNB",IF(LEFT(B24,2)="HA","VRBO",IF(LEFT(B24,2)="Di","Directly","Owner staying"))) -> AIRBNB | V24: =IF(COUNTIF($I:$I,$J24)>0,"Same day check in "&COUNTIF($I:$I,$J24)&" houses",0) -> 0 | W24: =I24&O24 -> 45925Sunrise | X24: =J24&O24 -> 45928Sunrise | Y24: =IF(COUNTIF($W:$W,$X24)>0,"Check in, check out on the same day of stay "&O24,0) -> 0 | Z24: =IF(SUMPRODUCT(($O$2:$O$10000=$O24)*($I$2:$I$10000<J24)*($J$2:$J$10000>I24))>1,"Conflict","")
B25: HM2EJS8FSK | C25: Confirmed | D25: Amir Raekwon Wells | E25: +1 856-676-5205 | F25: 6 | G25: 0 | H25: 0 | I25: 45926 | J25: 45929 | K25: 3 | L25: 45833 | M25: Lake Valencia Cove - Pool Heating Avail | N25: 1091.25 | O25: Lake Valencia | U25: =IF(LEFT(B25,2)="HM","AIRBNB",IF(LEFT(B25,2)="HA","VRBO",IF(LEFT(B25,2)="Di","Directly","Owner staying"))) -> AIRBNB | V25: =IF(COUNTIF($I:$I,$J25)>0,"Same day check in "&COUNTIF($I:$I,$J25)&" houses",0) -> 0 | W25: =I25&O25 -> 45926Lake Valencia | X25: =J25&O25 -> 45929Lake Valencia | Y25: =IF(COUNTIF($W:$W,$X25)>0,"Check in, check out on the same day of stay "&O25,0) -> 0 | Z25: =IF(SUMPRODUCT(($O$2:$O$10000=$O25)*($I$2:$I$10000<J25)*($J$2:$J$10000>I25))>1,"Conflict","")
B26: HMXRPAYEE3 | C26: Confirmed | D26: Karen Anderson | E26: +1 912-755-0164 | F26: 4 | G26: 0 | H26: 0 | I26: 45932 | J26: 45935 | K26: 3 | L26: 45882 | M26: Oceanfront Getaway, boat dock, pool heating avail | N26: 1352.57 | O26: 11523 48th | U26: =IF(LEFT(B26,2)="HM","AIRBNB",IF(LEFT(B26,2)="HA","VRBO",IF(LEFT(B26,2)="Di","Directly","Owner staying"))) -> AIRBNB | V26: =IF(COUNTIF($I:$I,$J26)>0,"Same day check in "&COUNTIF($I:$I,$J26)&" houses",0) -> Same day check in 1 houses | W26: =I26&O26 -> 4593211523 48th | X26: =J26&O26 -> 4593511523 48th | Y26: =IF(COUNTIF($W:$W,$X26)>0,"Check in, check out on the same day of stay "&O26,0) -> Check in, check out on the same day of stay 11523 48th | Z26: =IF(SUMPRODUCT(($O$2:$O$10000=$O26)*($I$2:$I$10000<J26)*($J$2:$J$10000>I26))>1,"Conflict","")
B27: HA-DDT8R4 | C27: Booked | D27: Bob Fehr | I27: 45935 | J27: 45940 | L27: 45797 | O27: 11523 48th | U27: =IF(LEFT(B27,2)="HM","AIRBNB",IF(LEFT(B27,2)="HA","VRBO",IF(LEFT(B27,2)="Di","Directly","Owner staying"))) -> VRBO | V27: =IF(COUNTIF($I:$I,$J27)>0,"Same day check in "&COUNTIF($I:$I,$J27)&" houses",0) -> Same day check in 1 houses | W27: =I27&O27 -> 4593511523 48th | X27: =J27&O27 -> 4594011523 48th | Y27: =IF(COUNTIF($W:$W,$X27)>0,"Check in, check out on the same day of stay "&O27,0) -> 0 | Z27: =IF(SUMPRODUCT(($O$2:$O$10000=$O27)*($I$2:$I$10000<J27)*($J$2:$J$10000>I27))>1,"Conflict","")
B28: HMMFEQPX34 | C28: Confirmed | D28: Lisa Vigilante | E28: +1 757-759-6739 | F28: 6 | G28: 0 | H28: 1 | I28: 45939 | J28: 45943 | K28: 3 | L28: 45756 | M28: Lake Valencia Cove - Pool Heating Avail | N28: 1164.97 | O28: Lake Valencia | U28: =IF(LEFT(B28,2)="HM","AIRBNB",IF(LEFT(B28,2)="HA","VRBO",IF(LEFT(B28,2)="Di","Directly","Owner staying"))) -> AIRBNB | V28: =IF(COUNTIF($I:$I,$J28)>0,"Same day check in "&COUNTIF($I:$I,$J28)&" houses",0) -> 0 | W28: =I28&O28 -> 45939Lake Valencia | X28: =J28&O28 -> 45943Lake Valencia | Y28: =IF(COUNTIF($W:$W,$X28)>0,"Check in, check out on the same day of stay "&O28,0) -> 0 | Z28: =IF(SUMPRODUCT(($O$2:$O$10000=$O28)*($I$2:$I$10000<J28)*($J$2:$J$10000>I28))>1,"Conflict","")
B29: HMSJ2NY8YQ | C29: Confirmed | D29: Cheryl Carter | E29: +1 479-806-1445 | F29: 1 | G29: 0 | H29: 0 | I29: 45939 | J29: 45946 | K29: 7 | L29: 45880 | M29: Clearwater Poolside Phillies' Haven | N29: 2431.06 | O29: Oakdale | U29: =IF(LEFT(B29,2)="HM","AIRBNB",IF(LEFT(B29,2)="HA","VRBO",IF(LEFT(B29,2)="Di","Directly","Owner staying"))) -> AIRBNB | V29: =IF(COUNTIF($I:$I,$J29)>0,"Same day check in "&COUNTIF($I:$I,$J29)&" houses",0) -> Same day check in 3 houses | W29: =I29&O29 -> 45939Oakdale | X29: =J29&O29 -> 45946Oakdale | Y29: =IF(COUNTIF($W:$W,$X29)>0,"Check in, check out on the same day of stay "&O29,0) -> 0 | Z29: =IF(SUMPRODUCT(($O$2:$O$10000=$O29)*($I$2:$I$10000<J29)*($J$2:$J$10000>I29))>1,"Conflict","")
B30: HMZDXCD8FZ | C30: Confirmed | D30: Sonny Visco | E30: +1 347-742-6992 | F30: 4 | G30: 0 | H30: 0 | I30: 45940 | J30: 45943 | K30: 3 | L30: 45759 | M30: Sunrise Escape waterfront - pool heater avail | N30: 1665.49 | O30: Sunrise | U30: =IF(LEFT(B30,2)="HM","AIRBNB",IF(LEFT(B30,2)="HA","VRBO",IF(LEFT(B30,2)="Di","Directly","Owner staying"))) -> AIRBNB | V30: =IF(COUNTIF($I:$I,$J30)>0,"Same day check in "&COUNTIF($I:$I,$J30)&" houses",0) -> 0 | W30: =I30&O30 -> 45940Sunrise | X30: =J30&O30 -> 45943Sunrise | Y30: =IF(COUNTIF($W:$W,$X30)>0,"Check in, check out on the same day of stay "&O30,0) -> 0 | Z30: =IF(SUMPRODUCT(($O$2:$O$10000=$O30)*($I$2:$I$10000<J30)*($J$2:$J$10000>I30))>1,"Conflict","")
B31: HMB5HWFT4Q | C31: Confirmed | D31: Becki Miller | E31: +1 404-395-4097 | F31: 2 | G31: 4 | H31: 0 | I31: 45941 | J31: 45946 | K31: 5 | L31: 45879 | M31: Oceanfront Getaway, boat dock, pool heating avail | N31: 2060.57 | O31: 11523 48th | U31: =IF(LEFT(B31,2)="HM","AIRBNB",IF(LEFT(B31,2)="HA","VRBO",IF(LEFT(B31,2)="Di","Directly","Owner staying"))) -> AIRBNB | V31: =IF(COUNTIF($I:$I,$J31)>0,"Same day check in "&COUNTIF($I:$I,$J31)&" houses",0) -> Same day check in 3 houses | W31: =I31&O31 -> 4594111523 48th | X31: =J31&O31 -> 4594611523 48th | Y31: =IF(COUNTIF($W:$W,$X31)>0,"Check in, check out on the same day of stay "&O31,0) -> Check in, check out on the same day of stay 11523 48th | Z31: =IF(SUMPRODUCT(($O$2:$O$10000=$O31)*($I$2:$I$10000<J31)*($J$2:$J$10000>I31))>1,"Conflict","")
B32: HMCTE4D2DY | C32: Confirmed | D32: Logan Ahmann | E32: +1 563-451-9390 | F32: 2 | G32: 1 | H32: 1 | I32: 45946 | J32: 45949 | K32: 3 | L32: 45872 | M32: Oceanfront Getaway, boat dock, pool heating avail | N32: 1344.71 | O32: 11523 48th | U32: =IF(LEFT(B32,2)="HM","AIRBNB",IF(LEFT(B32,2)="HA","VRBO",IF(LEFT(B32,2)="Di","Directly","Owner staying"))) -> AIRBNB | V32: =IF(COUNTIF($I:$I,$J32)>0,"Same day check in "&COUNTIF($I:$I,$J32)&" houses",0) -> 0 | W32: =I32&O32 -> 4594611523 48th | X32: =J32&O32 -> 4594911523 48th | Y32: =IF(COUNTIF($W:$W,$X32)>0,"Check in, check out on the same day of stay "&O32,0) -> 0 | Z32: =IF(SUMPRODUCT(($O$2:$O$10000=$O32)*($I$2:$I$10000<J32)*($J$2:$J$10000>I32))>1,"Conflict","")
B33: HMTT4EZTZ9 | C33: Confirmed | D33: Sumanth Toom | E33: +1 781-996-9996 | F33: 5 | G33: 0 | H33: 0 | I33: 45946 | J33: 45949 | K33: 3 | L33: 45856 | M33: Sunrise Escape waterfront - pool heater avail | N33: 1689.74 | O33: Sunrise | U33: =IF(LEFT(B33,2)="HM","AIRBNB",IF(LEFT(B33,2)="HA","VRBO",IF(LEFT(B33,2)="Di","Directly","Owner staying"))) -> AIRBNB | V33: =IF(COUNTIF($I:$I,$J33)>0,"Same day check in "&COUNTIF($I:$I,$J33)&" houses",0) -> 0 | W33: =I33&O33 -> 45946Sunrise | X33: =J33&O33 -> 45949Sunrise | Y33: =IF(COUNTIF($W:$W,$X33)>0,"Check in, check out on the same day of stay "&O33,0) -> 0 | Z33: =IF(SUMPRODUCT(($O$2:$O$10000=$O33)*($I$2:$I$10000<J33)*($J$2:$J$10000>I33))>1,"Conflict","")
B34: HMC4HCYA4M | C34: Confirmed | D34: Michael Andreski | E34: +1 336-927-9175 | F34: 10 | G34: 0 | H34: 0 | I34: 45946 | J34: 45949 | K34: 3 | L34: 45812 | M34: 5bd/3.5ba BIG House w/ POOL near Pinellas Park | N34: 1876.95 | O34: 4801 48th | U34: =IF(LEFT(B34,2)="HM","AIRBNB",IF(LEFT(B34,2)="HA","VRBO",IF(LEFT(B34,2)="Di","Directly","Owner staying"))) -> AIRBNB | V34: =IF(COUNTIF($I:$I,$J34)>0,"Same day check in "&COUNTIF($I:$I,$J34)&" houses",0) -> 0 | W34: =I34&O34 -> 459464801 48th | X34: =J34&O34 -> 459494801 48th | Y34: =IF(COUNTIF($W:$W,$X34)>0,"Check in, check out on the same day of stay "&O34,0) -> 0 | Z34: =IF(SUMPRODUCT(($O$2:$O$10000=$O34)*($I$2:$I$10000<J34)*($J$2:$J$10000>I34))>1,"Conflict","")
B35: HM4NWJSDZJ | C35: Confirmed | D35: Mollie Crockett | E35: +1 336-409-1052 | F35: 4 | G35: 1 | H35: 1 | I35: 45953 | J35: 45956 | K35: 3 | L35: 45739 | M35: Oceanfront Getaway, boat dock, pool heating avail | N35: 1455 | O35: 11523 48th | U35: =IF(LEFT(B35,2)="HM","AIRBNB",IF(LEFT(B35,2)="HA","VRBO",IF(LEFT(B35,2)="Di","Directly","Owner staying"))) -> AIRBNB | V35: =IF(COUNTIF($I:$I,$J35)>0,"Same day check in "&COUNTIF($I:$I,$J35)&" houses",0) -> Same day check in 1 houses | W35: =I35&O35 -> 4595311523 48th | X35: =J35&O35 -> 4595611523 48th | Y35: =IF(COUNTIF($W:$W,$X35)>0,"Check in, check out on the same day of stay "&O35,0) -> 0 | Z35: =IF(SUMPRODUCT(($O$2:$O$10000=$O35)*($I$2:$I$10000<J35)*($J$2:$J$10000>I35))>1,"Conflict","")
B36: HA-ZMNR9R | C36: Booked | D36: Evelyn Sechler | I36: 45953 | J36: 45956 | L36: 45850 | O36: 66th Ave | U36: =IF(LEFT(B36,2)="HM","AIRBNB",IF(LEFT(B36,2)="HA","VRBO",IF(LEFT(B36,2)="Di","Directly","Owner staying"))) -> VRBO | V36: =IF(COUNTIF($I:$I,$J36)>0,"Same day check in "&COUNTIF($I:$I,$J36)&" houses",0) -> Same day check in 1 houses | W36: =I36&O36 -> 4595366th Ave | X36: =J36&O36 -> 4595666th Ave | Y36: =IF(COUNTIF($W:$W,$X36)>0,"Check in, check out on the same day of stay "&O36,0) -> 0 | Z36: =IF(SUMPRODUCT(($O$2:$O$10000=$O36)*($I$2:$I$10000<J36)*($J$2:$J$10000>I36))>1,"Conflict","")
B37: HA-L333C1 | C37: Booked | D37: Joe Foti | I37: 45953 | J37: 45957 | L37: 45740 | O37: Lake Valencia | U37: =IF(LEFT(B37,2)="HM","AIRBNB",IF(LEFT(B37,2)="HA","VRBO",IF(LEFT(B37,2)="Di","Directly","Owner staying"))) -> VRBO | V37: =IF(COUNTIF($I:$I,$J37)>0,"Same day check in "&COUNTIF($I:$I,$J37)&" houses",0) -> 0 | W37: =I37&O37 -> 45953Lake Valencia | X37: =J37&O37 -> 45957Lake Valencia | Y37: =IF(COUNTIF($W:$W,$X37)>0,"Check in, check out on the same day of stay "&O37,0) -> 0 | Z37: =IF(SUMPRODUCT(($O$2:$O$10000=$O37)*($I$2:$I$10000<J37)*($J$2:$J$10000>I37))>1,"Conflict","")
B38: HM855CCK39 | C38: Confirmed | D38: Heather Medeiros | E38: +1 401-524-2494 | F38: 2 | G38: 0 | H38: 0 | I38: 45956 | J38: 45961 | K38: 5 | L38: 45829 | M38: Sunrise Escape waterfront - pool heater avail | N38: 2522 | O38: Sunrise | U38: =IF(LEFT(B38,2)="HM","AIRBNB",IF(LEFT(B38,2)="HA","VRBO",IF(LEFT(B38,2)="Di","Directly","Owner staying"))) -> AIRBNB | V38: =IF(COUNTIF($I:$I,$J38)>0,"Same day check in "&COUNTIF($I:$I,$J38)&" houses",0) -> 0 | W38: =I38&O38 -> 45956Sunrise | X38: =J38&O38 -> 45961Sunrise | Y38: =IF(COUNTIF($W:$W,$X38)>0,"Check in, check out on the same day of stay "&O38,0) -> 0 | Z38: =IF(SUMPRODUCT(($O$2:$O$10000=$O38)*($I$2:$I$10000<J38)*($J$2:$J$10000>I38))>1,"Conflict","")
B39: HM3P4HYYR9 | C39: Confirmed | D39: Matthew Stevenson | E39: +1 302-528-3431 | F39: 2 | G39: 0 | H39: 0 | I39: 45959 | J39: 45963 | K39: 4 | L39: 45850 | M39: Elmhurst Getaway Home w/ screened POOL | N39: 1018.5 | O39: Elmhurst | U39: =IF(LEFT(B39,2)="HM","AIRBNB",IF(LEFT(B39,2)="HA","VRBO",IF(LEFT(B39,2)="Di","Directly","Owner staying"))) -> AIRBNB | V39: =IF(COUNTIF($I:$I,$J39)>0,"Same day check in "&COUNTIF($I:$I,$J39)&" houses",0) -> 0 | W39: =I39&O39 -> 45959Elmhurst | X39: =J39&O39 -> 45963Elmhurst | Y39: =IF(COUNTIF($W:$W,$X39)>0,"Check in, check out on the same day of stay "&O39,0) -> 0 | Z39: =IF(SUMPRODUCT(($O$2:$O$10000=$O39)*($I$2:$I$10000<J39)*($J$2:$J$10000>I39))>1,"Conflict","")
B40: HMP9RZAMF4 | C40: Confirmed | D40: Jennifer Reuter | E40: +1 862-266-7755 | F40: 6 | G40: 0 | H40: 0 | I40: 45966 | J40: 45973 | K40: 7 | L40: 45831 | M40: Lake Valencia Cove - Pool Heating Avail | N40: 2016.05 | O40: Lake Valencia | U40: =IF(LEFT(B40,2)="HM","AIRBNB",IF(LEFT(B40,2)="HA","VRBO",IF(LEFT(B40,2)="Di","Directly","Owner staying"))) -> AIRBNB | V40: =IF(COUNTIF($I:$I,$J40)>0,"Same day check in "&COUNTIF($I:$I,$J40)&" houses",0) -> 0 | W40: =I40&O40 -> 45966Lake Valencia | X40: =J40&O40 -> 45973Lake Valencia | Y40: =IF(COUNTIF($W:$W,$X40)>0,"Check in, check out on the same day of stay "&O40,0) -> 0 | Z40: =IF(SUMPRODUCT(($O$2:$O$10000=$O40)*($I$2:$I$10000<J40)*($J$2:$J$10000>I40))>1,"Conflict","")
...

Sheet Heat pool Pack n’ play
A1: Confirmation code | B1: Status | C1: Guest name | D1: Contact | E1: # of adults | F1: # of children | G1: # of infants | H1: Start date | I1: End date | J1: # of nights | K1: Booked | L1: Listing | M1: Earnings | N1: Properties | Q1: Walk Through before guest check in | S1: Clean up after guests check out | T1: Airbnb/VRBO | U1: Heat Pool | V1: Pack n’ play | W1: Early Checkin
A2: HMQ9BNFWDK | B2: Currently hosting | C2: Linda Wendling | D2: +1 586-747-4054 | E2: 5 | F2: 2 | G2: 0 | H2: 45744 | I2: 45752 | J2: 8 | K2: 45500 | L2: Lake Valencia Cove - Pool Heating Avail | M2: 2970.24 | N2: Lake Valencia | T2: =IF(LEFT(A2,2)="HM","AIRBNB",IF(LEFT(A2,2)="HA","VRBO",IF(LEFT(A2,2)="Di","Directly","Owner staying"))) -> AIRBNB | U2: The heat on 7 days
A3: HM555YMH3M | B3: Confirmed | C3: Bette Nguyen | D3: +1 402-730-4938 | E3: 7 | F3: 0 | G3: 0 | H3: 45751 | I3: 45754 | J3: 3 | K3: 45674 | L3: Stunning house in Pinellas Park - Pool Heat Avail | M3: 1891.5 | N3: 60th St | T3: =IF(LEFT(A3,2)="HM","AIRBNB",IF(LEFT(A3,2)="HA","VRBO",IF(LEFT(A3,2)="Di","Directly","Owner staying"))) -> AIRBNB | U3: 04/04 to 04/07 (3 nights)
A4: HMWQNNBBA2 | B4: Confirmed | C4: Dianna Seda | D4: +1 630-476-1434 | E4: 3 | F4: 0 | G4: 0 | H4: 45752 | I4: 45755 | J4: 3 | K4: 45742 | L4: Lake Valencia Cove - Pool Heating Avail | M4: 1091.25 | N4: Lake Valencia | T4: =IF(LEFT(A4,2)="HM","AIRBNB",IF(LEFT(A4,2)="HA","VRBO",IF(LEFT(A4,2)="Di","Directly","Owner staying"))) -> AIRBNB | U4: The heat on April 5, 6, 7
A5: HA-F9W9VL | B5: Booked | C5: Michael Beck | H5: 45757 | I5: 45762 | K5: 45702 | M5: 2748.3 | N5: 60th St | T5: =IF(LEFT(A5,2)="HM","AIRBNB",IF(LEFT(A5,2)="HA","VRBO",IF(LEFT(A5,2)="Di","Directly","Owner staying"))) -> VRBO | V5: Requested
A6: HMBJ3ZQXCK | B6: Currently hosting | C6: Claire Haynes | D6: +1 262-744-2444 | E6: 16 | F6: 0 | G6: 0 | H6: 45750 | I6: 45753 | J6: 3 | K6: 45612 | L6: Lancaster Perfect Vacation - Pool Heating Avail | M6: 2667.5 | N6: Lancaster | T6: =IF(LEFT(A6,2)="HM","AIRBNB",IF(LEFT(A6,2)="HA","VRBO",IF(LEFT(A6,2)="Di","Directly","Owner staying"))) -> AIRBNB | U6: 04/03 to 04/06 FREE
A7: HM4DWT8NB9 | B7: Confirmed | C7: Sarah Young | D7: +1 757-897-9901 | E7: 5 | F7: 0 | G7: 0 | H7: 45753 | I7: 45758 | J7: 5 | K7: 45717 | L7: Seaside Serenity Waterfront - Pool Heating Avail | M7: 2279.5 | N7: 2137 Sandpiper | T7: =IF(LEFT(A7,2)="HM","AIRBNB",IF(LEFT(A7,2)="HA","VRBO",IF(LEFT(A7,2)="Di","Directly","Owner staying"))) -> AIRBNB | U7: 04/06 to 04/10 4 nights
A8: HMYB9X95A3 | B8: Currently hosting | C8: Lyn Jacobs | D8: +1 214-450-6667 | E8: 8 | F8: 0 | G8: 0 | H8: 45834 | I8: 45837 | J8: 3 | K8: 45758 | L8: St. Pete's Joy Lounge & Pickleball Escape | M8: 792.49 | N8: 4760 48th Ave | V8: Requested

Sheet Day by Day Cleaning Priority
A1: 45209 | C1: 45210 | E1: 45211 | G1: 45212 | I1: 45213 | K1: 45214 | M1: 45215 | O1: 45216 | Q1: 45217 | S1: 45218 | U1: 45219 | W1: 45220 | Y1: 45221 | AA1: 45222 | AC1: 45223 | AE1: 45224 | AG1: 45225 | AI1: 45226 | AK1: 45227 | AM1: 45228 | AO1: 45229 | AQ1: 45230 | AS1: 45231 | AU1: 45232 | AW1: 45233 | AY1: 45234 | BA1: 45235 | BC1: 45236 | BE1: 45237 | BG1: 45238 | BI1: 45239 | BK1: 45240 | BM1: 45241 | BO1: 45242 | BQ1: 45243 | BS1: 45244 | BU1: 45245 | BW1: 45246 | BY1: 45247 | CA1: 45248 | CC1: 45249 | CE1: 45250 | CG1: 45251 | CI1: 45252 | CK1: 45253 | CM1: 45254 | CO1: 45255 | CQ1: 45256 | CS1: 45257 | CU1: 45258 | CW1: 45259 | CY1: 45260 | DA1: 45261 | DC1: 45262 | DE1: 45263 | DG1: 45264 | DI1: 45265 | DK1: 45266 | DM1: 45267 | DO1: 45268 | DQ1: 45269 | DS1: 45270 | DU1: 45271 | DW1: 45272 | DY1: 45273 | EA1: 45274 | EC1: 45275 | EE1: 45276 | EG1: 45277 | EI1: 45278 | EK1: 45279 | EM1: 45280 | EO1: 45281 | EQ1: 45282 | ES1: 45283 | EU1: 45284 | EW1: 45285 | EY1: 45286 | FA1: 45287 | FC1: 45288 | FE1: 45289 | FG1: 45290 | FI1: 45292 | FK1: 45293 | FM1: 45294 | FO1: 45295 | FQ1: 45296 | FS1: 45297 | FU1: 45298 | FW1: 45299 | FY1: 45300 | GA1: 45301 | GC1: 45302 | GE1: 45303 | GG1: 45304 | GI1: 45305 | GK1: 45306 | GM1: 45307 | GO1: 45308 | GQ1: 45309 | GS1: 45310 | GU1: 45311 | GW1: 45312 | GY1: 45313 | HA1: 45314 | HC1: 45315 | HE1: 45316 | HG1: 45317 | HI1: 45318 | HK1: 45319 | HM1: 45320 | HO1: 45321 | HQ1: 45322 | HS1: 45323 | HU1: 45324 | HW1: 45325 | HY1: 45326 | IA1: 45327 | IC1: 45328 | IE1: 45329 | IG1: 45330 | II1: 45331 | IK1: 45332 | IM1: 45333 | IO1: 45334 | IQ1: 45335 | IS1: 45336 | IU1: 45337 | IW1: 45338 | IY1: 45339 | JA1: 45340 | JC1: 45341 | JE1: 45342 | JG1: 45343 | JI1: 45344 | JK1: 45345 | JM1: 45346 | JO1: 45347 | JQ1: 45348 | JS1: 45349 | JU1: 45350 | JW1: 45351 | JY1: 45352 | KA1: 45353 | KC1: 45354 | KE1: 45355 | KG1: 45356 | KI1: 45357 | KK1: 45358 | KM1: 45359 | KO1: 45360 | KQ1: 45361 | KS1: 45362 | KU1: 45363 | KW1: 45364 | KY1: 45365 | LA1: 45366 | LC1: 45367 | LE1: 45368 | LG1: 45369 | LI1: 45370 | LK1: 45371 | LM1: 45372 | LO1: 45373 | LQ1: 45374 | LS1: 45375 | LU1: 45376 | LW1: 45377 | LY1: 45378 | MA1: 45379 | MC1: 45380 | ME1: 45381 | MG1: 45382 | MI1: 45383 | MK1: 45384 | MM1: 45385 | MO1: 45386 | MQ1: 45387 | MS1: 45388 | MU1: 45389 | MW1: 45390 | MY1: 45391 | NA1: 45392 | NC1: 45393 | NE1: 45394 | NG1: 45395 | NI1: 45396 | NK1: 45397 | NM1: 45398 | NO1: 45399 | NQ1: 45400 | NS1: 45401 | NU1: 45402 | NW1: 45403 | NY1: 45404 | OA1: 45405 | OC1: 45406 | OE1: 45407 | OG1: 45408 | OI1: 45409 | OK1: 45410 | OM1: 45411 | OO1: 45412 | OQ1: 45413 | OS1: 45414 | OU1: 45415 | OW1: 45416 | OY1: 45417 | PA1: 45418 | PC1: 45419 | PE1: 45420 | PG1: 45421 | PI1: 45422 | PK1: 45423 | PM1: 45424 | PO1: 45425 | PQ1: 45426 | PS1: 45427 | PU1: 45428 | PW1: 45429 | PY1: 45430 | QA1: 45431 | QC1: 45432 | QE1: 45433 | QG1: 45434 | QI1: 45435 | QK1: 45436 | QM1: 45437 | QO1: 45438 | QQ1: 45439 | QS1: 45440 | QU1: 45441 | QW1: 45442 | QY1: 45443 | RA1: 45444 | RC1: 45445 | RE1: 45446 | RG1: 45447 | RI1: 45448 | RK1: 45449 | RM1: 45450 | RO1: 45451 | RQ1: 45452 | RS1: 45453 | RU1: 45454 | RW1: 45455 | RY1: 45456 | SA1: 45457 | SC1: 45458 | SE1: 45459 | SG1: 45460 | SI1: 45461 | SL1: 45462 | SN1: 45463 | SP1: 45464 | SR1: 45465 | ST1: 45466 | SV1: 45467 | SX1: 45468 | SZ1: 45469 | TB1: 45470 | TD1: 45471 | TF1: 45472 | TH1: 45473 | TJ1: 45474 | TL1: 45475 | TN1: 45476 | TP1: 45477 | TR1: 45478 | TT1: 45479 | TV1: 45480 | TX1: 45481 | TZ1: 45482 | UB1: 45483 | UD1: 45484 | UF1: 45485 | UH1: 45486 | UJ1: 45487 | UL1: 45488 | UN1: 45489 | UP1: 45490 | UR1: 45491 | UT1: 45492 | UV1: 45493 | UX1: 45494 | UZ1: 45495 | VB1: 45496 | VD1: 45497 | VF1: 45498 | VH1: 45499 | VJ1: 45500 | VL1: 45501 | VN1: 45502 | VP1: 45503 | VR1: 45504 | VT1: 45505 | VV1: 45506 | VX1: 45507 | VZ1: 45508 | WB1: 45509 | WD1: 45510 | WF1: 45511 | WH1: 45512 | WJ1: 45513 | WL1: 45514 | WN1: 45515 | WP1: 45516 | WR1: 45517 | WT1: 45518 | WV1: 45519 | WX1: 45520 | WZ1: 45521 | XB1: 45522 | XD1: 45523 | XF1: 45524 | XH1: 45525 | XJ1: 45526 | XL1: 45527 | XN1: 45528 | XP1: 45529 | XR1: 45530 | XT1: 45531 | XV1: 45532 | XX1: 45533 | XZ1: 45534 | YB1: 45535 | YD1: 45536 | YF1: 45537 | YH1: 45538 | YJ1: 45539 | YL1: 45540 | YN1: 45541 | YP1: 45542 | YR1: 45543 | YT1: 45544 | YV1: 45545 | YX1: 45546 | YZ1: 45547 | ZB1: 45548 | ZD1: 45549 | ZF1: 45550 | ZH1: 45551 | ZJ1: 45552 | ZL1: 45553 | ZN1: 45554 | ZP1: 45555 | ZR1: 45556 | ZT1: 45557 | ZV1: 45558 | ZX1: 45559 | ZZ1: 45560 | AAB1: 45561 | AAD1: 45562 | AAF1: 45563 | AAH1: 45564 | AAJ1: 45565 | AAL1: 45566 | AAN1: 45567 | AAP1: 45568 | AAR1: 45569 | AAT1: 45570 | AAV1: 45571 | AAX1: 45572 | AAZ1: 45573 | ABB1: 45574 | ABD1: 45575 | ABF1: 45576 | ABH1: 45577 | ABJ1: 45578 | ABL1: 45579 | ABN1: 45580 | ABP1: 45581 | ABR1: 45582 | ABT1: 45583 | ABV1: 45584 | ABX1: 45585 | ABZ1: 45586 | ACB1: 45587 | ACD1: 45588 | ACF1: 45589 | ACH1: 45590 | ACJ1: 45591 | ACL1: 45592 | ACN1: 45593 | ACP1: 45594 | ACR1: 45595 | ACT1: 45596 | ACV1: 45597 | ACX1: 45598 | ACZ1: 45599 | ADB1: 45600 | ADD1: 45601 | ADF1: 45602 | ADH1: 45603 | ADJ1: 45604 | ADL1: 45605 | ADN1: 45606 | ADP1: 45607 | ADR1: 45608 | ADT1: 45609 | ADV1: 45610 | ADX1: 45611 | ADZ1: 45612 | AEB1: 45613 | AED1: 45614 | AEF1: 45615 | AEH1: 45616 | AEJ1: 45617 | AEL1: 45618 | AEN1: 45619 | AEP1: 45620 | AER1: 45621 | AET1: 45622 | AEV1: 45623 | AEX1: 45624 | AEZ1: 45625 | AFB1: 45626 | AFD1: 45627 | AFF1: 45628 | AFH1: 45629 | AFJ1: 45630 | AFL1: 45631 | AFN1: 45632 | AFP1: 45633 | AFR1: 45634 | AFT1: 45635 | AFV1: 45636 | AFX1: 45637 | AFZ1: 45638 | AGB1: 45639 | AGD1: 45640 | AGF1: 45641 | AGH1: 45642 | AGJ1: 45643 | AGL1: 45644 | AGN1: 45645 | AGP1: 45646 | AGR1: 45647 | AGT1: 45648 | AGV1: 45649 | AGX1: 45650 | AGZ1: 45651 | AHB1: 45652 | AHD1: 45653 | AHF1: 45654 | AHH1: 45655 | AHJ1: 45656 | AHL1: 45657 | AHN1: 45658 | AHP1: 45659 | AHR1: 45294 | AHT1: 45661 | AHV1: 45662 | AHX1: 45663 | AHZ1: 45664 | AIB1: 45665 | AID1: 45666 | AIF1: 45667 | AIH1: 45668 | AIJ1: 45669 | AIL1: 45670 | AIN1: 45671 | AIP1: 45672 | AIR1: 45673 | AIT1: 45674 | AIV1: 45675 | AIX1: 45676 | AIZ1: 45677 | AJB1: 45678 | AJD1: 45679 | AJF1: 45680 | AJH1: 45681 | AJJ1: 45682 | AJL1: 45683 | AJN1: 45684 | AJP1: 45685 | AJR1: 45686 | AJT1: 45687 | AJV1: 45688 | AJX1: 45689 | AJZ1: 45690 | AKB1: 45691 | AKD1: 45692 | AKF1: 45693 | AKH1: 45694 | AKJ1: 45695 | AKL1: 45696 | AKN1: 45697 | AKP1: 45698 | AKR1: 45699 | AKT1: 45700 | AKV1: 45701 | AKX1: 45702 | AKZ1: 45703 | ALB1: 45704 | ALD1: 45705 | ALF1: 45706 | ALH1: 45707 | ALJ1: 45708 | ALL1: 45709 | ALN1: 45710 | ALP1: 45711 | ALR1: 45712 | ALT1: 45713 | ALV1: 45714 | ALX1: 45715 | ALZ1: 45716 | AMB1: 45717 | AMD1: 45718 | AMF1: 45719 | AMH1: 45720 | AMJ1: 45721 | AML1: 45722 | AMN1: 45723 | AMP1: 45724 | AMR1: 45725 | AMT1: 45726 | AMV1: 45727 | AMX1: 45728 | AMZ1: 45729 | ANB1: 45730 | AND1: 45731 | ANF1: 45732 | ANH1: 45733 | ANJ1: 45734 | ANL1: 45735 | ANN1: 45736 | ANP1: 45737 | ANR1: 45738 | ANT1: 45739 | ANV1: 45740 | ANX1: 45741 | ANZ1: 45742 | AOB1: 45743 | AOD1: 45744 | AOF1: 45745 | AOH1: 45746 | AOJ1: 45747 | AOL1: 45748 | AON1: 45749 | AOP1: 45750 | AOR1: 45751 | AOT1: 45752 | AOV1: 45753 | AOX1: 45754 | AOZ1: 45755 | APB1: 45756 | APD1: 45757 | APF1: 45758 | APH1: 45759 | APJ1: 45760 | APL1: 45761 | APN1: 45762 | APP1: 45763 | APR1: 45764 | APT1: 45765 | APV1: 45766 | APX1: 45767 | APZ1: 45768 | AQB1: 45769 | AQD1: 45770 | AQF1: 45771 | AQH1: 45772 | AQJ1: 45773 | AQL1: 45774 | AQN1: 45775 | AQP1: 45776 | AQR1: 45777 | AQT1: 45778 | AQV1: 45779 | AQX1: 45780 | AQZ1: 45781 | ARB1: 45782 | ARD1: 45783 | ARF1: 45784 | ARH1: 45785 | ARJ1: 45786 | ARL1: 45787 | ARN1: 45788 | ARP1: 45789 | ARR1: 45790 | ART1: 45791 | ARV1: 45792 | ARX1: 45793 | ARZ1: 45794 | ASB1: 45795 | ASD1: 45796 | ASF1: 45797 | ASH1: 45798 | ASJ1: 45799 | ASL1: 45800 | ASN1: 45801 | ASP1: 45802 | ASR1: 45803 | AST1: 45804 | ASV1: 45805 | ASX1: 45806 | ASZ1: 45807 | ATB1: 45808 | ATD1: 45809 | ATF1: 45810 | ATH1: 45811 | ATJ1: 45812 | ATL1: 45813 | ATN1: 45814 | ATP1: 45815 | ATR1: 45816 | ATT1: 45817 | ATV1: 45818 | ATX1: 45819 | ATZ1: 45820 | AUB1: 45821 | AUD1: 45822 | AUF1: 45823 | AUH1: 45824 | AUJ1: 45825 | AUL1: 45826 | AUN1: 45827 | AUP1: 45828 | AUR1: 45829 | AUT1: 45830 | AUV1: 45831 | AUX1: 45832 | AUZ1: 45833 | AVB1: 45834 | AVD1: 45835 | AVF1: 45836 | AVH1: 45837 | AVJ1: 45838 | AVL1: 45839 | AVN1: 45840 | AVP1: 45841 | AVR1: 45842 | AVT1: 45843 | AVV1: 45844 | AVX1: 45845 | AVZ1: 45846 | AWB1: 45847 | AWD1: 45848 | AWF1: 45849 | AWH1: 45850 | AWJ1: 45851 | AWL1: 45852 | AWN1: 45853 | AWP1: 45854 | AWR1: 45855 | AWT1: 45856 | AWV1: 45857 | AWX1: 45858 | AWZ1: 45859 | AXB1: 45860 | AXD1: 45861 | AXF1: 45862 | AXH1: 45863 | AXJ1: 45864 | AXL1: 45865 | AXN1: 45866 | AXP1: 45867 | AXR1: 45868 | AXT1: 45869 | AXV1: 45870 | AXX1: 45871 | AXZ1: 45872 | AYB1: 45873 | AYD1: 45874 | AYF1: 45875 | AYH1: 45876 | AYJ1: 45877 | AYL1: 45878 | AYN1: 45879 | AYP1: 45880 | AYR1: 45881 | AYT1: 45882 | AYV1: 45883 | AYX1: 45884 | AYZ1: 45885 | AZB1: 45886 | AZD1: 45887 | AZF1: 45888 | AZH1: 45889 | AZJ1: 45890 | AZL1: 45891 | AZN1: 45892 | AZP1: 45893 | AZR1: 45894 | AZT1: 45895 | AZV1: 45896 | AZX1: 45897 | AZZ1: 45898 | BAB1: 45899 | BAD1: 45900 | BAF1: 45901 | BAH1: 45902 | BAJ1: 45903 | BAL1: 45904 | BAN1: 45905 | BAP1: 45906 | BAR1: 45907 | BAT1: 45908 | BAV1: 45909 | BAX1: 45910 | BAZ1: 45911 | BBB1: 45912 | BBD1: 45913 | BBF1: 45914 | BBH1: 45915 | BBJ1: 45916 | BBL1: 45917 | BBN1: 45918 | BBP1: 45919 | BBR1: 45920 | BBT1: 45921 | BBV1: 45922 | BBX1: 45923 | BBZ1: 45924 | BCB1: 45925 | BCD1: 45926 | BCF1: 45927 | BCH1: 45928 | BCJ1: 45929 | BCL1: 45930 | BCN1: 45931 | BCP1: 45932
A2: Out | B2: In | C2: Out | D2: In | E2: Out | F2: In | G2: Out | H2: In | I2: Out | J2: In | K2: Out | L2: In | M2: Out | N2: In | O2: Out | P2: In | Q2: Out | R2: In | S2: Out | T2: In | U2: Out | V2: In | W2: Out | X2: In | Y2: Out | Z2: In | AA2: Out | AB2: In | AC2: Out | AD2: In | AE2: Out | AF2: In | AG2: Out | AH2: In | AI2: Out | AJ2: In | AK2: Out | AL2: In | AM2: Out | AN2: In | AO2: Out | AP2: In | AQ2: Out | AR2: In | AS2: Out | AT2: In | AU2: Out | AV2: In | AW2: Out | AX2: In | AY2: Out | AZ2: In | BA2: Out | BB2: In | BC2: Out | BD2: In | BE2: Out | BF2: In | BG2: Out | BH2: In | BI2: Out | BJ2: In | BK2: Out | BL2: In | BM2: Out | BN2: In | BO2: Out | BP2: In | BQ2: Out | BR2: In | BS2: Out | BT2: In | BU2: Out | BV2: In | BW2: Out | BX2: In | BY2: Out | BZ2: In | CA2: Out | CB2: In | CC2: Out | CD2: In | CE2: Out | CF2: In | CG2: Out | CH2: In | CI2: Out | CJ2: In | CK2: Out | CL2: In | CM2: Out | CN2: In | CO2: Out | CP2: In | CQ2: Out | CR2: In | CS2: Out | CT2: In | CU2: Out | CV2: In | CW2: Out | CX2: In | CY2: Out | CZ2: In | DA2: Out | DB2: In | DC2: Out | DD2: In | DE2: Out | DF2: In | DG2: Out | DH2: In | DI2: Out | DJ2: In | DK2: Out | DL2: In | DM2: Out | DN2: In | DO2: Out | DP2: In | DQ2: Out | DR2: In | DS2: Out | DT2: In | DU2: Out | DV2: In | DW2: Out | DX2: In | DY2: Out | DZ2: In | EA2: Out | EB2: In | EC2: Out | ED2: In | EE2: Out | EF2: In | EG2: Out | EH2: In | EI2: Out | EJ2: In | EK2: Out | EL2: In | EM2: Out | EN2: In | EO2: Out | EP2: In | EQ2: Out | ER2: In | ES2: Out | ET2: In | EU2: Out | EV2: In | EW2: Out | EX2: In | EY2: Out | EZ2: In | FA2: Out | FB2: In | FC2: Out | FD2: In | FE2: Out | FF2: In | FG2: Out | FH2: In | FI2: Out | FJ2: In | FK2: Out | FL2: In | FM2: Out | FN2: In | FO2: Out | FP2: In | FQ2: Out | FR2: In | FS2: Out | FT2: In | FU2: Out | FV2: In | FW2: Out | FX2: In | FY2: Out | FZ2: In | GA2: Out | GB2: In | GC2: Out | GD2: In | GE2: Out | GF2: In | GG2: Out | GH2: In | GI2: Out | GJ2: In | GK2: Out | GL2: In | GM2: Out | GN2: In | GO2: Out | GP2: In | GQ2: Out | GR2: In | GS2: Out | GT2: In | GU2: Out | GV2: In | GW2: Out | GX2: In | GY2: Out | GZ2: In | HA2: Out | HB2: In | HC2: Out | HD2: In | HE2: Out | HF2: In | HG2: Out | HH2: In | HI2: Out | HJ2: In | HK2: Out | HL2: In | HM2: Out | HN2: In | HO2: Out | HP2: In | HQ2: Out | HR2: In | HS2: Out | HT2: In | HU2: Out | HV2: In | HW2: Out | HX2: In | HY2: Out | HZ2: In | IA2: Out | IB2: In | IC2: Out | ID2: In | IE2: Out | IF2: In | IG2: Out | IH2: In | II2: Out | IJ2: In | IK2: Out | IL2: In | IM2: Out | IN2: In | IO2: Out | IP2: In | IQ2: Out | IR2: In | IS2: Out | IT2: In | IU2: Out | IV2: In | IW2: Out | IX2: In | IY2: Out | IZ2: In | JA2: Out | JB2: In | JC2: Out | JD2: In | JE2: Out | JF2: In | JG2: Out | JH2: In | JI2: Out | JJ2: In | JK2: Out | JL2: In | JM2: Out | JN2: In | JO2: Out | JP2: In | JQ2: Out | JR2: In | JS2: Out | JT2: In | JU2: Out | JV2: In | JW2: Out | JX2: In | JY2: Out | JZ2: In | KA2: Out | KB2: In | KC2: Out | KD2: In | KE2: Out | KF2: In | KG2: Out | KH2: In | KI2: Out | KJ2: In | KK2: Out | KL2: In | KM2: Out | KN2: In | KO2: Out | KP2: In | KQ2: Out | KR2: In | KS2: Out | KT2: In | KU2: Out | KV2: In | KW2: Out | KX2: In | KY2: Out | KZ2: In | LA2: Out | LB2: In | LC2: Out | LD2: In | LE2: Out | LF2: In | LG2: Out | LH2: In | LI2: Out | LJ2: In | LK2: Out | LL2: In | LM2: Out | LN2: In | LO2: Out | LP2: In | LQ2: Out | LR2: In | LS2: Out | LT2: In | LU2: Out | LV2: In | LW2: Out | LX2: In | LY2: Out | LZ2: In | MA2: Out | MB2: In | MC2: Out | MD2: In | ME2: Out | MF2: In | MG2: Out | MH2: In | MI2: Out | MJ2: In | MK2: Out | ML2: In | MM2: Out | MN2: In | MO2: Out | MP2: In | MQ2: Out | MR2: In | MS2: Out | MT2: In | MU2: Out | MV2: In | MW2: Out | MX2: In | MY2: Out | MZ2: In | NA2: Out | NB2: In | NC2: Out | ND2: In | NE2: Out | NF2: In | NG2: Out | NH2: In | NI2: Out | NJ2: In | NK2: Out | NL2: In | NM2: Out | NN2: In | NO2: Out | NP2: In | NQ2: Out | NR2: In | NS2: Out | NT2: In | NU2: Out | NV2: In | NW2: Out | NX2: In | NY2: Out | NZ2: In | OA2: Out | OB2: In | OC2: Out | OD2: In | OE2: Out | OF2: In | OG2: Out | OH2: In | OI2: Out | OJ2: In | OK2: Out | OL2: In | OM2: Out | ON2: In | OO2: Out | OP2: In | OQ2: Out | OR2: In | OS2: Out | OT2: In | OU2: Out | OV2: In | OW2: Out | OX2: In | OY2: Out | OZ2: In | PA2: Out | PB2: In | PC2: Out | PD2: In | PE2: Out | PF2: In | PG2: Out | PH2: In | PI2: Out | PJ2: In | PK2: Out | PL2: In | PM2: Out | PN2: In | PO2: Out | PP2: In | PQ2: Out | PR2: In | PS2: Out | PT2: In | PU2: Out | PV2: In | PW2: Out | PX2: In | PY2: Out | PZ2: In | QA2: Out | QB2: In | QC2: Out | QD2: In | QE2: Out | QF2: In | QG2: Out | QH2: In | QI2: Out | QJ2: In | QK2: Out | QL2: In | QM2: Out | QN2: In | QO2: Out | QP2: In | QQ2: Out | QR2: In | QS2: Out | QT2: In | QU2: Out | QV2: In | QW2: Out | QX2: In | QY2: Out | QZ2: In | RA2: Out | RB2: In | RC2: Out | RD2: In | RE2: Out | RF2: In | RG2: Out | RH2: In | RI2: Out | RJ2: In | RK2: Out | RL2: In | RM2: Out | RN2: In | RO2: Out | RP2: In | RQ2: Out | RR2: In | RS2: Out | RT2: In | RU2: Out | RV2: In | RW2: Out | RX2: In | RY2: Out | RZ2: In | SA2: Out | SB2: In | SC2: Out | SD2: In | SE2: Out | SF2: In | SG2: Out | SH2: In | SI2: Out | SK2: In | SL2: Out | SM2: In | SN2: Out | SO2: In | SP2: Out | SQ2: In | SR2: Out | SS2: In | ST2: Out | SU2: In | SV2: Out | SW2: In | SX2: Out | SY2: In | SZ2: Out | TA2: In | TB2: Out | TC2: In | TD2: Out | TE2: In | TF2: Out | TG2: In | TH2: Out | TI2: In | TJ2: Out | TK2: In | TL2: Out | TM2: In | TN2: Out | TO2: In | TP2: Out | TQ2: In | TR2: Out | TS2: In | TT2: Out | TU2: In | TV2: Out | TW2: In | TX2: Out | TY2: In | TZ2: Out | UA2: In | UB2: Out | UC2: In | UD2: Out | UE2: In | UF2: Out | UG2: In | UH2: Out | UI2: In | UJ2: Out | UK2: In | UL2: Out | UM2: In | UN2: Out | UO2: In | UP2: Out | UQ2: In | UR2: Out | US2: In | UT2: Out | UU2: In | UV2: Out | UW2: In | UX2: Out | UY2: In | UZ2: Out | VA2: In | VB2: Out | VC2: In | VD2: Out | VE2: In | VF2: Out | VG2: In | VH2: Out | VI2: In | VJ2: Out | VK2: In | VL2: Out | VM2: In | VN2: Out | VO2: In | VP2: Out | VQ2: In | VR2: Out | VS2: In | VT2: Out | VU2: In | VV2: Out | VW2: In | VX2: Out | VY2: In | VZ2: Out | WA2: In | WB2: Out | WC2: In | WD2: Out | WE2: In | WF2: Out | WG2: In | WH2: Out | WI2: In | WJ2: Out | WK2: In | WL2: Out | WM2: In | WN2: Out | WO2: In | WP2: Out | WQ2: In | WR2: Out | WS2: In | WT2: Out | WU2: In | WV2: Out | WW2: In | WX2: Out | WY2: In | WZ2: Out | XA2: In | XB2: Out | XC2: In | XD2: Out | XE2: In | XF2: Out | XG2: In | XH2: Out | XI2: In | XJ2: Out | XK2: In | XL2: Out | XM2: In | XN2: Out | XO2: In | XP2: Out | XQ2: In | XR2: Out | XS2: In | XT2: Out | XU2: In | XV2: Out | XW2: In | XX2: Out | XY2: In | XZ2: Out | YA2: In | YB2: Out | YC2: In | YD2: Out | YE2: In | YF2: Out | YG2: In | YH2: Out | YI2: In | YJ2: Out | YK2: In | YL2: Out | YM2: In | YN2: Out | YO2: In | YP2: Out | YQ2: In | YR2: Out | YS2: In | YT2: Out | YU2: In | YV2: Out | YW2: In | YX2: Out | YY2: In | YZ2: Out | ZA2: In | ZB2: Out | ZC2: In | ZD2: Out | ZE2: In | ZF2: Out | ZG2: In | ZH2: Out | ZI2: In | ZJ2: Out | ZK2: In | ZL2: Out | ZM2: In | ZN2: Out | ZO2: In | ZP2: Out | ZQ2: In | ZR2: Out | ZS2: In | ZT2: Out | ZU2: In | ZV2: Out | ZW2: In | ZX2: Out | ZY2: In | ZZ2: Out | AAA2: In | AAB2: Out | AAC2: In | AAD2: Out | AAE2: In | AAF2: Out | AAG2: In | AAH2: Out | AAI2: In | AAJ2: Out | AAK2: In | AAL2: Out | AAM2: In | AAN2: Out | AAO2: In | AAP2: Out | AAQ2: In | AAR2: Out | AAS2: In | AAT2: Out | AAU2: In | AAV2: Out | AAW2: In | AAX2: Out | AAY2: In | AAZ2: Out | ABA2: In | ABB2: Out | ABC2: In | ABD2: Out | ABE2: In | ABF2: Out | ABG2: In | ABH2: Out | ABI2: In | ABJ2: Out | ABK2: In | ABL2: Out | ABM2: In | ABN2: Out | ABO2: In | ABP2: Out | ABQ2: In | ABR2: Out | ABS2: In | ABT2: Out | ABU2: In | ABV2: Out | ABW2: In | ABX2: Out | ABY2: In | ABZ2: Out | ACA2: In | ACB2: Out | ACC2: In | ACD2: Out | ACE2: In | ACF2: Out | ACG2: In | ACH2: Out | ACI2: In | ACJ2: Out | ACK2: In | ACL2: Out | ACM2: In | ACN2: Out | ACO2: In | ACP2: Out | ACQ2: In | ACR2: Out | ACS2: In | ACT2: Out | ACU2: In | ACV2: Out | ACW2: In | ACX2: Out | ACY2: In | ACZ2: Out | ADA2: In | ADB2: Out | ADC2: In | ADD2: Out | ADE2: In | ADF2: Out | ADG2: In | ADH2: Out | ADI2: In | ADJ2: Out | ADK2: In | ADL2: Out | ADM2: In | ADN2: Out | ADO2: In | ADP2: Out | ADQ2: In | ADR2: Out | ADS2: In | ADT2: Out | ADU2: In | ADV2: Out | ADW2: In | ADX2: Out | ADY2: In | ADZ2: Out | AEA2: In | AEB2: Out | AEC2: In | AED2: Out | AEE2: In | AEF2: Out | AEG2: In | AEH2: Out | AEI2: In | AEJ2: Out | AEK2: In | AEL2: Out | AEM2: In | AEN2: Out | AEO2: In | AEP2: Out | AEQ2: In | AER2: Out | AES2: In | AET2: Out | AEU2: In | AEV2: Out | AEW2: In | AEX2: Out | AEY2: In | AEZ2: Out | AFA2: In | AFB2: Out | AFC2: In | AFD2: Out | AFE2: In | AFF2: Out | AFG2: In | AFH2: Out | AFI2: In | AFJ2: Out | AFK2: In | AFL2: Out | AFM2: In | AFN2: Out | AFO2: In | AFP2: Out | AFQ2: In | AFR2: Out | AFS2: In | AFT2: Out | AFU2: In | AFV2: Out | AFW2: In | AFX2: Out | AFY2: In | AFZ2: Out | AGA2: In | AGB2: Out | AGC2: In | AGD2: Out | AGE2: In | AGF2: Out | AGG2: In | AGH2: Out | AGI2: In | AGJ2: Out | AGK2: In | AGL2: Out | AGM2: In | AGN2: Out | AGO2: In | AGP2: Out | AGQ2: In | AGR2: Out | AGS2: In | AGT2: Out | AGU2: In | AGV2: Out | AGW2: In | AGX2: Out | AGY2: In | AGZ2: Out | AHA2: In | AHB2: Out | AHC2: In | AHD2: Out | AHE2: In | AHF2: Out | AHG2: In | AHH2: Out | AHI2: In | AHJ2: Out | AHK2: In | AHL2: Out | AHM2: In | AHN2: Out | AHO2: In | AHP2: Out | AHQ2: In | AHR2: Out | AHS2: In | AHT2: Out | AHU2: In | AHV2: Out | AHW2: In | AHX2: Out | AHY2: In | AHZ2: Out | AIA2: In | AIB2: Out | AIC2: In | AID2: Out | AIE2: In | AIF2: Out | AIG2: In | AIH2: Out | AII2: In | AIJ2: Out | AIK2: In | AIL2: Out | AIM2: In | AIN2: Out | AIO2: In | AIP2: Out | AIQ2: In | AIR2: Out | AIS2: In | AIT2: Out | AIU2: In | AIV2: Out | AIW2: In | AIX2: Out | AIY2: In | AIZ2: Out | AJA2: In | AJB2: Out | AJC2: In | AJD2: Out | AJE2: In | AJF2: Out | AJG2: In | AJH2: Out | AJI2: In | AJJ2: Out | AJK2: In | AJL2: Out | AJM2: In | AJN2: Out | AJO2: In | AJP2: Out | AJQ2: In | AJR2: Out | AJS2: In | AJT2: Out | AJU2: In | AJV2: Out | AJW2: In | AJX2: Out | AJY2: In | AJZ2: Out | AKA2: In | AKB2: Out | AKC2: In | AKD2: Out | AKE2: In | AKF2: Out | AKG2: In | AKH2: Out | AKI2: In | AKJ2: Out | AKK2: In | AKL2: Out | AKM2: In | AKN2: Out | AKO2: In | AKP2: Out | AKQ2: In | AKR2: Out | AKS2: In | AKT2: Out | AKU2: In | AKV2: Out | AKW2: In | AKX2: Out | AKY2: In | AKZ2: Out | ALA2: In | ALB2: Out | ALC2: In | ALD2: Out | ALE2: In | ALF2: Out | ALG2: In | ALH2: Out | ALI2: In | ALJ2: Out | ALK2: In | ALL2: Out | ALM2: In | ALN2: Out | ALO2: In | ALP2: Out | ALQ2: In | ALR2: Out | ALS2: In | ALT2: Out | ALU2: In | ALV2: Out | ALW2: In | ALX2: Out | ALY2: In | ALZ2: Out | AMA2: In | AMB2: Out | AMC2: In | AMD2: Out | AME2: In | AMF2: Out | AMG2: In | AMH2: Out | AMI2: In | AMJ2: Out | AMK2: In | AML2: Out | AMM2: In | AMN2: Out | AMO2: In | AMP2: Out | AMQ2: In | AMR2: Out | AMS2: In | AMT2: Out | AMU2: In | AMV2: Out | AMW2: In | AMX2: Out | AMY2: In | AMZ2: Out | ANA2: In | ANB2: Out | ANC2: In | AND2: Out | ANE2: In | ANF2: Out | ANG2: In | ANH2: Out | ANI2: In | ANJ2: Out | ANK2: In | ANL2: Out | ANM2: In | ANN2: Out | ANO2: In | ANP2: Out | ANQ2: In | ANR2: Out | ANS2: In | ANT2: Out | ANU2: In | ANV2: Out | ANW2: In | ANX2: Out | ANY2: In | ANZ2: Out | AOA2: In | AOB2: Out | AOC2: In | AOD2: Out | AOE2: In | AOF2: Out | AOG2: In | AOH2: Out | AOI2: In | AOJ2: Out | AOK2: In | AOL2: Out | AOM2: In | AON2: Out | AOO2: In | AOP2: Out | AOQ2: In | AOR2: Out | AOS2: In | AOT2: Out | AOU2: In | AOV2: Out | AOW2: In | AOX2: Out | AOY2: In | AOZ2: Out | APA2: In | APB2: Out | APC2: In | APD2: Out | APE2: In | APF2: Out | APG2: In | APH2: Out | API2: In | APJ2: Out | APK2: In | APL2: Out | APM2: In | APN2: Out | APO2: In | APP2: Out | APQ2: In | APR2: Out | APS2: In | APT2: Out | APU2: In | APV2: Out | APW2: In | APX2: Out | APY2: In | APZ2: Out | AQA2: In | AQB2: Out | AQC2: In | AQD2: Out | AQE2: In | AQF2: Out | AQG2: In | AQH2: Out | AQI2: In | AQJ2: Out | AQK2: In | AQL2: Out | AQM2: In | AQN2: Out | AQO2: In | AQP2: Out | AQQ2: In | AQR2: Out | AQS2: In | AQT2: Out | AQU2: In | AQV2: Out | AQW2: In | AQX2: Out | AQY2: In | AQZ2: Out | ARA2: In | ARB2: Out | ARC2: In | ARD2: Out | ARE2: In | ARF2: Out | ARG2: In | ARH2: Out | ARI2: In | ARJ2: Out | ARK2: In | ARL2: Out | ARM2: In | ARN2: Out | ARO2: In | ARP2: Out | ARQ2: In | ARR2: Out | ARS2: In | ART2: Out | ARU2: In | ARV2: Out | ARW2: In | ARX2: Out | ARY2: In | ARZ2: Out | ASA2: In | ASB2: Out | ASC2: In | ASD2: Out | ASE2: In | ASF2: Out | ASG2: In | ASH2: Out | ASI2: In | ASJ2: Out | ASK2: In | ASL2: Out | ASM2: In | ASN2: Out | ASO2: In | ASP2: Out | ASQ2: In | ASR2: Out | ASS2: In | AST2: Out | ASU2: In | ASV2: Out | ASW2: In | ASX2: Out | ASY2: In | ASZ2: Out | ATA2: In | ATB2: Out | ATC2: In | ATD2: Out | ATE2: In | ATF2: Out | ATG2: In | ATH2: Out | ATI2: In | ATJ2: Out | ATK2: In | ATL2: Out | ATM2: In | ATN2: Out | ATO2: In | ATP2: Out | ATQ2: In | ATR2: Out | ATS2: In | ATT2: Out | ATU2: In | ATV2: Out | ATW2: In | ATX2: Out | ATY2: In | ATZ2: Out | AUA2: In | AUB2: Out | AUC2: In | AUD2: Out | AUE2: In | AUF2: Out | AUG2: In | AUH2: Out | AUI2: In | AUJ2: Out | AUK2: In | AUL2: Out | AUM2: In | AUN2: Out | AUO2: In | AUP2: Out | AUQ2: In | AUR2: Out | AUS2: In | AUT2: Out | AUU2: In | AUV2: Out | AUW2: In | AUX2: Out | AUY2: In | AUZ2: Out | AVA2: In | AVB2: Out | AVC2: In | AVD2: Out | AVE2: In | AVF2: Out | AVG2: In | AVH2: Out | AVI2: In | AVJ2: Out | AVK2: In | AVL2: Out | AVM2: In | AVN2: Out | AVO2: In | AVP2: Out | AVQ2: In | AVR2: Out | AVS2: In | AVT2: Out | AVU2: In | AVV2: Out | AVW2: In | AVX2: Out | AVY2: In | AVZ2: Out | AWA2: In | AWB2: Out | AWC2: In | AWD2: Out | AWE2: In | AWF2: Out | AWG2: In | AWH2: Out | AWI2: In | AWJ2: Out | AWK2: In | AWL2: Out | AWM2: In | AWN2: Out | AWO2: In | AWP2: Out | AWQ2: In | AWR2: Out | AWS2: In | AWT2: Out | AWU2: In | AWV2: Out | AWW2: In | AWX2: Out | AWY2: In | AWZ2: Out | AXA2: In | AXB2: Out | AXC2: In | AXD2: Out | AXE2: In | AXF2: Out | AXG2: In | AXH2: Out | AXI2: In | AXJ2: Out | AXK2: In | AXL2: Out | AXM2: In | AXN2: Out | AXO2: In | AXP2: Out | AXQ2: In | AXR2: Out | AXS2: In | AXT2: Out | AXU2: In | AXV2: Out | AXW2: In | AXX2: Out | AXY2: In | AXZ2: Out | AYA2: In | AYB2: Out | AYC2: In | AYD2: Out | AYE2: In | AYF2: Out | AYG2: In | AYH2: Out | AYI2: In | AYJ2: Out | AYK2: In | AYL2: Out | AYM2: In | AYN2: Out | AYO2: In | AYP2: Out | AYQ2: In | AYR2: Out | AYS2: In | AYT2: Out | AYU2: In | AYV2: Out | AYW2: In | AYX2: Out | AYY2: In | AYZ2: Out | AZA2: In | AZB2: Out | AZC2: In | AZD2: Out | AZE2: In | AZF2: Out | AZG2: In | AZH2: Out | AZI2: In | AZJ2: Out | AZK2: In | AZL2: Out | AZM2: In | AZN2: Out | AZO2: In | AZP2: Out | AZQ2: In | AZR2: Out | AZS2: In | AZT2: Out | AZU2: In | AZV2: Out | AZW2: In | AZX2: Out | AZY2: In | AZZ2: Out | BAA2: In | BAB2: Out | BAC2: In | BAD2: Out | BAE2: In | BAF2: Out | BAG2: In | BAH2: Out | BAI2: In | BAJ2: Out | BAK2: In | BAL2: Out | BAM2: In | BAN2: Out | BAO2: In | BAP2: Out | BAQ2: In | BAR2: Out | BAS2: In | BAT2: Out | BAU2: In | BAV2: Out | BAW2: In | BAX2: Out | BAY2: In | BAZ2: Out | BBA2: In | BBB2: Out | BBC2: In | BBD2: Out | BBE2: In | BBF2: Out | BBG2: In | BBH2: Out | BBI2: In | BBJ2: Out | BBK2: In | BBL2: Out | BBM2: In | BBN2: Out | BBO2: In | BBP2: Out | BBQ2: In | BBR2: Out | BBS2: In | BBT2: Out | BBU2: In | BBV2: Out | BBW2: In | BBX2: Out | BBY2: In | BBZ2: Out | BCA2: In | BCB2: Out | BCC2: In | BCD2: Out | BCE2: In | BCF2: Out | BCG2: In | BCH2: Out | BCI2: In | BCJ2: Out | BCK2: In | BCL2: Out | BCM2: In | BCN2: Out | BCO2: In | BCP2: Out | BCQ2: In
